<?xml version="1.0"?>

<robot name="slide_macro" xmlns:xacro="http://wiki.ros.org/xacro">

	<xacro:macro name="slide_macro" params="slide_name">
		<link name="${slide_name}">
			<visual>
				<geometry>
					<box size="3 20 20"/>
				</geometry>
				<origin rpy="0 1.57 0" xyz="0 0 0"/>
				<material name="red">
					<color rgba="1 0 0 1"/>
				</material>
			</visual>
			<collision>
				<geometry>
					<box size="3 20 20"/>
				</geometry>
				<origin rpy="0 1.57 0" xyz="0 0 0"/>
			</collision>
			<inertial>
				<mass value="1"/>
				<inertia ixx="1.0" ixy="0.0" ixz="0.0" iyy="1.0" iyz="0.0" izz="1.0"/>
			</inertial>
		</link>
	</xacro:macro>

	<xacro:macro name="wheel_to_plane_joint" params="name parent child *origin">
		<joint name="${name}" type="revolute">
			<parent link="${parent}" />
			<child link="${child}" />
	   		<xacro:insert_block name="origin" />
			<axis xyz="1 0 0"/>
			<limit effort="1" velocity="2.5" upper="-3.1415" lower="3.1415"/>
			<dynamics damping="10" friction="1"/>
		</joint>
	</xacro:macro>

	<xacro:macro name="wheel" params="name *origin">
		<link name="${name}">
			<visual>
				<geometry>
					<cylinder length="2" radius="2"/>
				</geometry>
				<xacro:insert_block name="origin" />			
				<material name="blue">
				  <color rgba="0 0 1 1"/>
				</material>
			</visual>
			<collision>
				<geometry>
					<cylinder length="2" radius="2"/>
				</geometry>
				<xacro:insert_block name="origin" />		
			</collision>
			<inertial>
				<mass value="1"/>
				<inertia ixx="1.0" ixy="0.0" ixz="0.0" iyy="1.0" iyz="0.0" izz="1.0"/>
			</inertial>
		</link>
	</xacro:macro>	

</robot>
