<?xml version="1.0" encoding="utf-8"?>
<!-- =================================================================================== -->
<!-- |    This document was autogenerated by xacro from slide.xacro                    | -->
<!-- |    EDITING THIS FILE BY HAND IS NOT RECOMMENDED                                 | -->
<!-- =================================================================================== -->
<robot name="slide">
  <link name="slide">
    <visual>
      <geometry>
        <box size="3 20 20"/>
      </geometry>
      <origin rpy="0 1.57 0" xyz="0 0 0"/>
      <material name="red">
        <color rgba="1 0 0 1"/>
      </material>
    </visual>
    <collision>
      <geometry>
        <box size="3 20 20"/>
      </geometry>
      <origin rpy="0 1.57 0" xyz="0 0 0"/>
    </collision>
    <inertial>
      <mass value="1"/>
      <inertia ixx="1.0" ixy="0.0" ixz="0.0" iyy="1.0" iyz="0.0" izz="1.0"/>
    </inertial>
  </link>
  <joint name="front_whell_dx_joint" type="revolute">
    <parent link="slide"/>
    <child link="front_whell_dx"/>
    <origin xyz="8 7.5 -3.5"/>
    <axis xyz="1 0 0"/>
    <limit effort="1" lower="3.1415" upper="-3.1415" velocity="2.5"/>
    <dynamics damping="10" friction="1"/>
  </joint>
  <link name="front_whell_dx">
    <visual>
      <geometry>
        <cylinder length="2" radius="2"/>
      </geometry>
      <origin rpy="0 1.57 0" xyz="0 0 0"/>
      <material name="blue">
        <color rgba="0 0 1 1"/>
      </material>
    </visual>
    <collision>
      <geometry>
        <cylinder length="2" radius="2"/>
      </geometry>
      <origin rpy="0 1.57 0" xyz="0 0 0"/>
    </collision>
    <inertial>
      <mass value="1"/>
      <inertia ixx="1.0" ixy="0.0" ixz="0.0" iyy="1.0" iyz="0.0" izz="1.0"/>
    </inertial>
  </link>
  <joint name="front_whell_sx_joint" type="revolute">
    <parent link="slide"/>
    <child link="front_whell_sx"/>
    <origin xyz="-8 7.5 -3.5"/>
    <axis xyz="1 0 0"/>
    <limit effort="1" lower="3.1415" upper="-3.1415" velocity="2.5"/>
    <dynamics damping="10" friction="1"/>
  </joint>
  <link name="front_whell_sx">
    <visual>
      <geometry>
        <cylinder length="2" radius="2"/>
      </geometry>
      <origin rpy="0 1.57 0" xyz="0 0 0"/>
      <material name="blue">
        <color rgba="0 0 1 1"/>
      </material>
    </visual>
    <collision>
      <geometry>
        <cylinder length="2" radius="2"/>
      </geometry>
      <origin rpy="0 1.57 0" xyz="0 0 0"/>
    </collision>
    <inertial>
      <mass value="1"/>
      <inertia ixx="1.0" ixy="0.0" ixz="0.0" iyy="1.0" iyz="0.0" izz="1.0"/>
    </inertial>
  </link>
  <joint name="rear_whell_dx_joint" type="revolute">
    <parent link="slide"/>
    <child link="rear_whell_dx"/>
    <origin xyz="8 -7.5 -3.5"/>
    <axis xyz="1 0 0"/>
    <limit effort="1" lower="3.1415" upper="-3.1415" velocity="2.5"/>
    <dynamics damping="10" friction="1"/>
  </joint>
  <link name="rear_whell_dx">
    <visual>
      <geometry>
        <cylinder length="2" radius="2"/>
      </geometry>
      <origin rpy="0 1.57 0" xyz="0 0 0"/>
      <material name="blue">
        <color rgba="0 0 1 1"/>
      </material>
    </visual>
    <collision>
      <geometry>
        <cylinder length="2" radius="2"/>
      </geometry>
      <origin rpy="0 1.57 0" xyz="0 0 0"/>
    </collision>
    <inertial>
      <mass value="1"/>
      <inertia ixx="1.0" ixy="0.0" ixz="0.0" iyy="1.0" iyz="0.0" izz="1.0"/>
    </inertial>
  </link>
  <joint name="rear_whell_sx_joint" type="revolute">
    <parent link="slide"/>
    <child link="rear_whell_sx"/>
    <origin xyz="-8 -7.5 -3.5"/>
    <axis xyz="1 0 0"/>
    <limit effort="1" lower="3.1415" upper="-3.1415" velocity="2.5"/>
    <dynamics damping="10" friction="1"/>
  </joint>
  <link name="rear_whell_sx">
    <visual>
      <geometry>
        <cylinder length="2" radius="2"/>
      </geometry>
      <origin rpy="0 1.57 0" xyz="0 0 0"/>
      <material name="blue">
        <color rgba="0 0 1 1"/>
      </material>
    </visual>
    <collision>
      <geometry>
        <cylinder length="2" radius="2"/>
      </geometry>
      <origin rpy="0 1.57 0" xyz="0 0 0"/>
    </collision>
    <inertial>
      <mass value="1"/>
      <inertia ixx="1.0" ixy="0.0" ixz="0.0" iyy="1.0" iyz="0.0" izz="1.0"/>
    </inertial>
  </link>
  <!-- robot_to_slide_joint-->
  <joint name="robot_to_slide" type="fixed">
    <parent link="slide"/>
    <child link="base_link"/>
    <origin xyz="0 0 1.5"/>
  </joint>
  <link name="base_link">
    <visual>
      <geometry>
        <cylinder length="5" radius="8"/>
      </geometry>
      <origin rpy="0 0 0" xyz="0 0 2.5"/>
      <material name="yellow">
        <color rgba="1 1 0 1"/>
      </material>
    </visual>
    <collision>
      <geometry>
        <cylinder length="5" radius="8"/>
      </geometry>
      <origin rpy="0 0 0" xyz="0 0 2.5"/>
    </collision>
    <inertial>
      <mass value="1"/>
      <inertia ixx="1.0" ixy="0.0" ixz="0.0" iyy="1.0" iyz="0.0" izz="1.0"/>
    </inertial>
  </link>
  <joint name="first_joint" type="revolute">
    <parent link="base_link"/>
    <child link="first_link"/>
    <origin xyz="0 0 0"/>
    <axis xyz="0 0 1"/>
    <limit effort="176" lower="-2.97" upper="2.97" velocity="1.96"/>
    <dynamics damping="50" friction="1"/>
  </joint>
  <link name="first_link">
    <visual>
      <geometry>
        <cylinder length="20" radius="5"/>
      </geometry>
      <origin rpy="0 0 0" xyz="0 0 15"/>
      <material name="blue">
        <color rgba="0 0 1 1"/>
      </material>
    </visual>
    <collision>
      <geometry>
        <cylinder length="20" radius="5"/>
      </geometry>
      <origin rpy="0 0 0" xyz="0 0 15"/>
    </collision>
    <inertial>
      <mass value="1"/>
      <inertia ixx="1.0" ixy="0.0" ixz="0.0" iyy="1.0" iyz="0.0" izz="1.0"/>
    </inertial>
  </link>
  <joint name="second_joint" type="revolute">
    <parent link="first_link"/>
    <child link="second_link"/>
    <origin xyz="0 0 20"/>
    <axis xyz="1 0 0"/>
    <limit effort="176" lower="-2.09" upper="2.09" velocity="1.96"/>
    <dynamics damping="50" friction="1"/>
  </joint>
  <link name="second_link">
    <visual>
      <geometry>
        <cylinder length="20" radius="5"/>
      </geometry>
      <origin rpy="0 1.57 0" xyz="10 0 0"/>
      <material name="blue">
        <color rgba="0 0 1 1"/>
      </material>
    </visual>
    <collision>
      <geometry>
        <cylinder length="20" radius="5"/>
      </geometry>
      <origin rpy="0 1.57 0" xyz="10 0 0"/>
    </collision>
    <inertial>
      <mass value="1"/>
      <inertia ixx="1.0" ixy="0.0" ixz="0.0" iyy="1.0" iyz="0.0" izz="1.0"/>
    </inertial>
  </link>
  <joint name="third_joint" type="revolute">
    <parent link="second_link"/>
    <child link="third_link"/>
    <origin xyz="15 0 0"/>
    <axis xyz="0 0 1"/>
    <limit effort="110" lower="-2.97" upper="2.97" velocity="2"/>
    <dynamics damping="50" friction="1"/>
  </joint>
  <link name="third_link">
    <visual>
      <geometry>
        <cylinder length="40" radius="5"/>
      </geometry>
      <origin rpy="0 0 0" xyz="0 0 20"/>
      <material name="blue">
        <color rgba="0 0 1 1"/>
      </material>
    </visual>
    <collision>
      <geometry>
        <cylinder length="40" radius="5"/>
      </geometry>
      <origin rpy="0 0 0" xyz="0 0 20"/>
    </collision>
    <inertial>
      <mass value="1"/>
      <inertia ixx="1.0" ixy="0.0" ixz="0.0" iyy="1.0" iyz="0.0" izz="1.0"/>
    </inertial>
  </link>
  <joint name="forth_joint" type="revolute">
    <parent link="third_link"/>
    <child link="fourth_link"/>
    <origin xyz="0 0 35"/>
    <axis xyz="1 0 0"/>
    <limit effort="110" lower="-2.09" upper="2.09" velocity="2.6"/>
    <dynamics damping="50" friction="1"/>
  </joint>
  <link name="fourth_link">
    <visual>
      <geometry>
        <cylinder length="20" radius="5"/>
      </geometry>
      <origin rpy="0 1.57 0" xyz="-10 0 0"/>
      <material name="blue">
        <color rgba="0 0 1 1"/>
      </material>
    </visual>
    <collision>
      <geometry>
        <cylinder length="20" radius="5"/>
      </geometry>
      <origin rpy="0 1.57 0" xyz="-10 0 0"/>
    </collision>
    <inertial>
      <mass value="1"/>
      <inertia ixx="1.0" ixy="0.0" ixz="0.0" iyy="1.0" iyz="0.0" izz="1.0"/>
    </inertial>
  </link>
  <joint name="fifth_joint" type="revolute">
    <parent link="fourth_link"/>
    <child link="fifth_link"/>
    <origin xyz="-15 0 0"/>
    <axis xyz="0 0 1"/>
    <limit effort="110" lower="-2.97" upper="2.97" velocity="2.8"/>
    <dynamics damping="50" friction="1"/>
  </joint>
  <link name="fifth_link">
    <visual>
      <geometry>
        <cylinder length="40" radius="5"/>
      </geometry>
      <origin rpy="0 0 0" xyz="0 0 20"/>
      <material name="blue">
        <color rgba="0 0 1 1"/>
      </material>
    </visual>
    <collision>
      <geometry>
        <cylinder length="40" radius="5"/>
      </geometry>
      <origin rpy="0 0 0" xyz="0 0 20"/>
    </collision>
    <inertial>
      <mass value="1"/>
      <inertia ixx="1.0" ixy="0.0" ixz="0.0" iyy="1.0" iyz="0.0" izz="1.0"/>
    </inertial>
  </link>
  <joint name="sixth_joint" type="revolute">
    <parent link="fifth_link"/>
    <child link="sixth_link"/>
    <origin xyz="0 0 35"/>
    <axis xyz="1 0 0"/>
    <limit effort="40" lower="-2.09" upper="2.09" velocity="3.6"/>
    <dynamics damping="50" friction="1"/>
  </joint>
  <link name="sixth_link">
    <visual>
      <geometry>
        <cylinder length="20" radius="5"/>
      </geometry>
      <origin rpy="0 1.57 0" xyz="10 0 0"/>
      <material name="blue">
        <color rgba="0 0 1 1"/>
      </material>
    </visual>
    <collision>
      <geometry>
        <cylinder length="20" radius="5"/>
      </geometry>
      <origin rpy="0 1.57 0" xyz="10 0 0"/>
    </collision>
    <inertial>
      <mass value="1"/>
      <inertia ixx="1.0" ixy="0.0" ixz="0.0" iyy="1.0" iyz="0.0" izz="1.0"/>
    </inertial>
  </link>
  <joint name="seventh_joint" type="revolute">
    <parent link="sixth_link"/>
    <child link="seventh_link"/>
    <origin xyz="15 0 0"/>
    <axis xyz="0 0 1"/>
    <limit effort="40" lower="-3.05" upper="3.05" velocity="3.6"/>
    <dynamics damping="50" friction="1"/>
  </joint>
  <link name="seventh_link">
    <visual>
      <geometry>
        <cylinder length="20" radius="5"/>
      </geometry>
      <origin rpy="0 0 0" xyz="0 0 10"/>
      <material name="blue">
        <color rgba="0 0 1 1"/>
      </material>
    </visual>
    <collision>
      <geometry>
        <cylinder length="20" radius="5"/>
      </geometry>
      <origin rpy="0 0 0" xyz="0 0 10"/>
    </collision>
    <inertial>
      <mass value="1"/>
      <inertia ixx="1.0" ixy="0.0" ixz="0.0" iyy="1.0" iyz="0.0" izz="1.0"/>
    </inertial>
  </link>
</robot>

